<?xml version='1.0' encoding='utf-8'?>
<robot name="partnet_64bc6e2a_63d2_44a3_a3ca_907796900279">
	<link name="base" />
	<link name="link_0">
		<visual name="knob_11">
			<origin xyz="-0.2681379098855239 -0.144322 0" />
			<geometry>
				<mesh filename="textured_objs_isaac/original_17.obj" />
			</geometry>
		</visual>
		<collision>
			<origin xyz="-0.2681379098855239 -0.144322 0" />
			<geometry>
				<mesh filename="textured_objs_isaac/original_17.obj" />
			</geometry>
		</collision>
	</link>
	<joint name="joint_0" type="continuous">
		<origin xyz="0.2681379098855239 0.144322 0" />
		<axis xyz="0 0 1" />
		<child link="link_0" />
		<parent link="link_15" />
	</joint>
	<link name="link_1">
		<visual name="knob_12">
			<origin xyz="-0.25933771414546697 -0.384801 0" />
			<geometry>
				<mesh filename="textured_objs_isaac/original_50.obj" />
			</geometry>
		</visual>
		<collision>
			<origin xyz="-0.25933771414546697 -0.384801 0" />
			<geometry>
				<mesh filename="textured_objs_isaac/original_50.obj" />
			</geometry>
		</collision>
	</link>
	<joint name="joint_1" type="continuous">
		<origin xyz="0.25933771414546697 0.384801 0" />
		<axis xyz="0 0 1" />
		<child link="link_1" />
		<parent link="link_15" />
	</joint>
	<link name="link_2">
		<visual name="knob_13">
			<origin xyz="-0.25933783825624923 -0.47934483825624924 0" />
			<geometry>
				<mesh filename="textured_objs_isaac/original_51.obj" />
			</geometry>
		</visual>
		<collision>
			<origin xyz="-0.25933783825624923 -0.47934483825624924 0" />
			<geometry>
				<mesh filename="textured_objs_isaac/original_51.obj" />
			</geometry>
		</collision>
	</link>
	<joint name="joint_2" type="continuous">
		<origin xyz="0.25933783825624923 0.47934483825624924 0" />
		<axis xyz="0 0 1" />
		<child link="link_2" />
		<parent link="link_15" />
	</joint>
	<link name="link_3">
		<visual name="knob_14">
			<origin xyz="-0.25933780190451805 -0.5733298856305807 0" />
			<geometry>
				<mesh filename="textured_objs_isaac/original_52.obj" />
			</geometry>
		</visual>
		<collision>
			<origin xyz="-0.25933780190451805 -0.5733298856305807 0" />
			<geometry>
				<mesh filename="textured_objs_isaac/original_52.obj" />
			</geometry>
		</collision>
	</link>
	<joint name="joint_3" type="continuous">
		<origin xyz="0.25933780190451805 0.5733298856305807 0" />
		<axis xyz="0 0 1" />
		<child link="link_3" />
		<parent link="link_15" />
	</joint>
	<link name="link_4">
		<visual name="knob_25">
			<origin xyz="-0.16216417498097713 -0.15836158958464766 -0.5327349999999993" />
			<geometry>
				<mesh filename="textured_objs_isaac/original_16.obj" />
			</geometry>
		</visual>
		<collision>
			<origin xyz="-0.16216417498097713 -0.15836158958464766 -0.5327349999999993" />
			<geometry>
				<mesh filename="textured_objs_isaac/original_16.obj" />
			</geometry>
		</collision>
	</link>
	<joint name="joint_4" type="revolute">
		<origin xyz="0.16216417498097713 0.15836158958464766 0.5327349999999993" />
		<axis xyz="0 0 -1" />
		<child link="link_4" />
		<parent link="link_15" />
		<limit lower="-0.767944870877505" upper="1.5707963267948966" />
	</joint>
	<link name="link_5">
		<visual name="container_36">
			<origin xyz="0.225338 0 -0.2089295" />
			<geometry>
				<mesh filename="textured_objs_isaac/original_4.obj" />
			</geometry>
		</visual>
		<visual name="container_36">
			<origin xyz="0.225338 0 -0.2089295" />
			<geometry>
				<mesh filename="textured_objs_isaac/original_5.obj" />
			</geometry>
		</visual>
		<visual name="container_36">
			<origin xyz="0.225338 0 -0.2089295" />
			<geometry>
				<mesh filename="textured_objs_isaac/original_9.obj" />
			</geometry>
		</visual>
		<visual name="container_36">
			<origin xyz="0.225338 0 -0.2089295" />
			<geometry>
				<mesh filename="textured_objs_isaac/original_6.obj" />
			</geometry>
		</visual>
		<visual name="container_36">
			<origin xyz="0.225338 0 -0.2089295" />
			<geometry>
				<mesh filename="textured_objs_isaac/original_10.obj" />
			</geometry>
		</visual>
		<collision>
			<origin xyz="0.225338 0 -0.2089295" />
			<geometry>
				<mesh filename="textured_objs_isaac/original_4.obj" />
			</geometry>
		</collision>
		<collision>
			<origin xyz="0.225338 0 -0.2089295" />
			<geometry>
				<mesh filename="textured_objs_isaac/original_5.obj" />
			</geometry>
		</collision>
		<collision>
			<origin xyz="0.225338 0 -0.2089295" />
			<geometry>
				<mesh filename="textured_objs_isaac/original_9.obj" />
			</geometry>
		</collision>
		<collision>
			<origin xyz="0.225338 0 -0.2089295" />
			<geometry>
				<mesh filename="textured_objs_isaac/original_6.obj" />
			</geometry>
		</collision>
		<collision>
			<origin xyz="0.225338 0 -0.2089295" />
			<geometry>
				<mesh filename="textured_objs_isaac/original_10.obj" />
			</geometry>
		</collision>
	</link>
	<joint name="joint_5" type="revolute">
		<origin xyz="-0.225338 0 0.2089295" />
		<axis xyz="0 -1 0" />
		<child link="link_5" />
		<parent link="link_15" />
		<limit lower="-0.722566310325652" upper="2.2242475987415733" />
	</joint>
	<link name="link_6">
		<visual name="button_38">
			<origin xyz="0 0 0" />
			<geometry>
				<mesh filename="textured_objs_isaac/original_64.obj" />
			</geometry>
		</visual>
		<collision>
			<origin xyz="0 0 0" />
			<geometry>
				<mesh filename="textured_objs_isaac/original_64.obj" />
			</geometry>
		</collision>
	</link>
	<joint name="joint_6" type="prismatic">
		<origin xyz="0 0 0" />
		<axis xyz="0 0 -1" />
		<child link="link_6" />
		<parent link="link_15" />
		<limit lower="0" upper="0.008000000000000007" />
	</joint>
	<link name="link_7">
		<visual name="button_39">
			<origin xyz="0 0 0" />
			<geometry>
				<mesh filename="textured_objs_isaac/original_63.obj" />
			</geometry>
		</visual>
		<collision>
			<origin xyz="0 0 0" />
			<geometry>
				<mesh filename="textured_objs_isaac/original_63.obj" />
			</geometry>
		</collision>
	</link>
	<joint name="joint_7" type="prismatic">
		<origin xyz="0 0 0" />
		<axis xyz="0 0 -1" />
		<child link="link_7" />
		<parent link="link_15" />
		<limit lower="0" upper="0.008000000000000007" />
	</joint>
	<link name="link_8">
		<visual name="button_40">
			<origin xyz="0 0 0" />
			<geometry>
				<mesh filename="textured_objs_isaac/original_62.obj" />
			</geometry>
		</visual>
		<collision>
			<origin xyz="0 0 0" />
			<geometry>
				<mesh filename="textured_objs_isaac/original_62.obj" />
			</geometry>
		</collision>
	</link>
	<joint name="joint_8" type="prismatic">
		<origin xyz="0 0 0" />
		<axis xyz="0 0 -1" />
		<child link="link_8" />
		<parent link="link_15" />
		<limit lower="0" upper="0.008000000000000007" />
	</joint>
	<link name="link_9">
		<visual name="button_41">
			<origin xyz="0 0 0" />
			<geometry>
				<mesh filename="textured_objs_isaac/original_60.obj" />
			</geometry>
		</visual>
		<collision>
			<origin xyz="0 0 0" />
			<geometry>
				<mesh filename="textured_objs_isaac/original_60.obj" />
			</geometry>
		</collision>
	</link>
	<joint name="joint_9" type="prismatic">
		<origin xyz="0 0 0" />
		<axis xyz="0 0 -1" />
		<child link="link_9" />
		<parent link="link_15" />
		<limit lower="0" upper="0.008000000000000007" />
	</joint>
	<link name="link_10">
		<visual name="button_42">
			<origin xyz="0 0 0" />
			<geometry>
				<mesh filename="textured_objs_isaac/original_59.obj" />
			</geometry>
		</visual>
		<collision>
			<origin xyz="0 0 0" />
			<geometry>
				<mesh filename="textured_objs_isaac/original_59.obj" />
			</geometry>
		</collision>
	</link>
	<joint name="joint_10" type="prismatic">
		<origin xyz="0 0 0" />
		<axis xyz="0 0 -1" />
		<child link="link_10" />
		<parent link="link_15" />
		<limit lower="0" upper="0.008000000000000007" />
	</joint>
	<link name="link_11">
		<visual name="button_43">
			<origin xyz="0 0 0" />
			<geometry>
				<mesh filename="textured_objs_isaac/original_58.obj" />
			</geometry>
		</visual>
		<collision>
			<origin xyz="0 0 0" />
			<geometry>
				<mesh filename="textured_objs_isaac/original_58.obj" />
			</geometry>
		</collision>
	</link>
	<joint name="joint_11" type="prismatic">
		<origin xyz="0 0 0" />
		<axis xyz="0 0 -1" />
		<child link="link_11" />
		<parent link="link_15" />
		<limit lower="0" upper="0.008000000000000007" />
	</joint>
	<link name="link_12">
		<visual name="button_44">
			<origin xyz="0 0 0" />
			<geometry>
				<mesh filename="textured_objs_isaac/original_56.obj" />
			</geometry>
		</visual>
		<collision>
			<origin xyz="0 0 0" />
			<geometry>
				<mesh filename="textured_objs_isaac/original_56.obj" />
			</geometry>
		</collision>
	</link>
	<joint name="joint_12" type="prismatic">
		<origin xyz="0 0 0" />
		<axis xyz="0 0 -1" />
		<child link="link_12" />
		<parent link="link_15" />
		<limit lower="0" upper="0.008000000000000007" />
	</joint>
	<link name="link_13">
		<visual name="button_45">
			<origin xyz="0 0 0" />
			<geometry>
				<mesh filename="textured_objs_isaac/original_55.obj" />
			</geometry>
		</visual>
		<collision>
			<origin xyz="0 0 0" />
			<geometry>
				<mesh filename="textured_objs_isaac/original_55.obj" />
			</geometry>
		</collision>
	</link>
	<joint name="joint_13" type="prismatic">
		<origin xyz="0 0 0" />
		<axis xyz="0 0 -1" />
		<child link="link_13" />
		<parent link="link_15" />
		<limit lower="0" upper="0.008000000000000007" />
	</joint>
	<link name="link_14">
		<visual name="button_46">
			<origin xyz="0 0 0" />
			<geometry>
				<mesh filename="textured_objs_isaac/original_54.obj" />
			</geometry>
		</visual>
		<collision>
			<origin xyz="0 0 0" />
			<geometry>
				<mesh filename="textured_objs_isaac/original_54.obj" />
			</geometry>
		</collision>
	</link>
	<joint name="joint_14" type="prismatic">
		<origin xyz="0 0 0" />
		<axis xyz="0 0 -1" />
		<child link="link_14" />
		<parent link="link_15" />
		<limit lower="0" upper="0.008000000000000007" />
	</joint>
	<link name="link_15">
		<visual name="base_body_48">
			<origin xyz="0 0 0" />
			<geometry>
				<mesh filename="textured_objs_isaac/original_29.obj" />
			</geometry>
		</visual>
		<visual name="base_body_48">
			<origin xyz="0 0 0" />
			<geometry>
				<mesh filename="textured_objs_isaac/original_30.obj" />
			</geometry>
		</visual>
		<visual name="base_body_48">
			<origin xyz="0 0 0" />
			<geometry>
				<mesh filename="textured_objs_isaac/original_36.obj" />
			</geometry>
		</visual>
		<visual name="base_body_48">
			<origin xyz="0 0 0" />
			<geometry>
				<mesh filename="textured_objs_isaac/original_41.obj" />
			</geometry>
		</visual>
		<visual name="base_body_48">
			<origin xyz="0 0 0" />
			<geometry>
				<mesh filename="textured_objs_isaac/original_43.obj" />
			</geometry>
		</visual>
		<visual name="base_body_48">
			<origin xyz="0 0 0" />
			<geometry>
				<mesh filename="textured_objs_isaac/original_22.obj" />
			</geometry>
		</visual>
		<visual name="base_body_48">
			<origin xyz="0 0 0" />
			<geometry>
				<mesh filename="textured_objs_isaac/original_26.obj" />
			</geometry>
		</visual>
		<visual name="base_body_48">
			<origin xyz="0 0 0" />
			<geometry>
				<mesh filename="textured_objs_isaac/original_65.obj" />
			</geometry>
		</visual>
		<visual name="base_body_48">
			<origin xyz="0 0 0" />
			<geometry>
				<mesh filename="textured_objs_isaac/original_33.obj" />
			</geometry>
		</visual>
		<visual name="base_body_48">
			<origin xyz="0 0 0" />
			<geometry>
				<mesh filename="textured_objs_isaac/original_44.obj" />
			</geometry>
		</visual>
		<visual name="base_body_48">
			<origin xyz="0 0 0" />
			<geometry>
				<mesh filename="textured_objs_isaac/original_8.obj" />
			</geometry>
		</visual>
		<visual name="base_body_48">
			<origin xyz="0 0 0" />
			<geometry>
				<mesh filename="textured_objs_isaac/original_45.obj" />
			</geometry>
		</visual>
		<visual name="base_body_48">
			<origin xyz="0 0 0" />
			<geometry>
				<mesh filename="textured_objs_isaac/original_35.obj" />
			</geometry>
		</visual>
		<visual name="base_body_48">
			<origin xyz="0 0 0" />
			<geometry>
				<mesh filename="textured_objs_isaac/original_39.obj" />
			</geometry>
		</visual>
		<visual name="base_body_48">
			<origin xyz="0 0 0" />
			<geometry>
				<mesh filename="textured_objs_isaac/original_27.obj" />
			</geometry>
		</visual>
		<visual name="base_body_48">
			<origin xyz="0 0 0" />
			<geometry>
				<mesh filename="textured_objs_isaac/original_31.obj" />
			</geometry>
		</visual>
		<visual name="base_body_48">
			<origin xyz="0 0 0" />
			<geometry>
				<mesh filename="textured_objs_isaac/original_37.obj" />
			</geometry>
		</visual>
		<visual name="base_body_48">
			<origin xyz="0 0 0" />
			<geometry>
				<mesh filename="textured_objs_isaac/original_48.obj" />
			</geometry>
		</visual>
		<visual name="base_body_48">
			<origin xyz="0 0 0" />
			<geometry>
				<mesh filename="textured_objs_isaac/original_23.obj" />
			</geometry>
		</visual>
		<visual name="base_body_48">
			<origin xyz="0 0 0" />
			<geometry>
				<mesh filename="textured_objs_isaac/original_67.obj" />
			</geometry>
		</visual>
		<visual name="base_body_48">
			<origin xyz="0 0 0" />
			<geometry>
				<mesh filename="textured_objs_isaac/original_38.obj" />
			</geometry>
		</visual>
		<visual name="base_body_48">
			<origin xyz="0 0 0" />
			<geometry>
				<mesh filename="textured_objs_isaac/original_68.obj" />
			</geometry>
		</visual>
		<visual name="base_body_48">
			<origin xyz="0 0 0" />
			<geometry>
				<mesh filename="textured_objs_isaac/original_34.obj" />
			</geometry>
		</visual>
		<visual name="base_body_48">
			<origin xyz="0 0 0" />
			<geometry>
				<mesh filename="textured_objs_isaac/original_42.obj" />
			</geometry>
		</visual>
		<visual name="base_body_48">
			<origin xyz="0 0 0" />
			<geometry>
				<mesh filename="textured_objs_isaac/original_20.obj" />
			</geometry>
		</visual>
		<visual name="base_body_48">
			<origin xyz="0 0 0" />
			<geometry>
				<mesh filename="textured_objs_isaac/original_32.obj" />
			</geometry>
		</visual>
		<visual name="base_body_48">
			<origin xyz="0 0 0" />
			<geometry>
				<mesh filename="textured_objs_isaac/original_47.obj" />
			</geometry>
		</visual>
		<visual name="base_body_48">
			<origin xyz="0 0 0" />
			<geometry>
				<mesh filename="textured_objs_isaac/original_40.obj" />
			</geometry>
		</visual>
		<visual name="base_body_48">
			<origin xyz="0 0 0" />
			<geometry>
				<mesh filename="textured_objs_isaac/original_46.obj" />
			</geometry>
		</visual>
		<collision>
			<origin xyz="0 0 0" />
			<geometry>
				<mesh filename="textured_objs_isaac/original_29.obj" />
			</geometry>
		</collision>
		<collision>
			<origin xyz="0 0 0" />
			<geometry>
				<mesh filename="textured_objs_isaac/original_30.obj" />
			</geometry>
		</collision>
		<collision>
			<origin xyz="0 0 0" />
			<geometry>
				<mesh filename="textured_objs_isaac/original_36.obj" />
			</geometry>
		</collision>
		<collision>
			<origin xyz="0 0 0" />
			<geometry>
				<mesh filename="textured_objs_isaac/original_41.obj" />
			</geometry>
		</collision>
		<collision>
			<origin xyz="0 0 0" />
			<geometry>
				<mesh filename="textured_objs_isaac/original_43.obj" />
			</geometry>
		</collision>
		<collision>
			<origin xyz="0 0 0" />
			<geometry>
				<mesh filename="textured_objs_isaac/original_22.obj" />
			</geometry>
		</collision>
		<collision>
			<origin xyz="0 0 0" />
			<geometry>
				<mesh filename="textured_objs_isaac/original_26.obj" />
			</geometry>
		</collision>
		<collision>
			<origin xyz="0 0 0" />
			<geometry>
				<mesh filename="textured_objs_isaac/original_65.obj" />
			</geometry>
		</collision>
		<collision>
			<origin xyz="0 0 0" />
			<geometry>
				<mesh filename="textured_objs_isaac/original_33.obj" />
			</geometry>
		</collision>
		<collision>
			<origin xyz="0 0 0" />
			<geometry>
				<mesh filename="textured_objs_isaac/original_44.obj" />
			</geometry>
		</collision>
		<collision>
			<origin xyz="0 0 0" />
			<geometry>
				<mesh filename="textured_objs_isaac/original_8.obj" />
			</geometry>
		</collision>
		<collision>
			<origin xyz="0 0 0" />
			<geometry>
				<mesh filename="textured_objs_isaac/original_45.obj" />
			</geometry>
		</collision>
		<collision>
			<origin xyz="0 0 0" />
			<geometry>
				<mesh filename="textured_objs_isaac/original_35.obj" />
			</geometry>
		</collision>
		<collision>
			<origin xyz="0 0 0" />
			<geometry>
				<mesh filename="textured_objs_isaac/original_39.obj" />
			</geometry>
		</collision>
		<collision>
			<origin xyz="0 0 0" />
			<geometry>
				<mesh filename="textured_objs_isaac/original_27.obj" />
			</geometry>
		</collision>
		<collision>
			<origin xyz="0 0 0" />
			<geometry>
				<mesh filename="textured_objs_isaac/original_31.obj" />
			</geometry>
		</collision>
		<collision>
			<origin xyz="0 0 0" />
			<geometry>
				<mesh filename="textured_objs_isaac/original_37.obj" />
			</geometry>
		</collision>
		<collision>
			<origin xyz="0 0 0" />
			<geometry>
				<mesh filename="textured_objs_isaac/original_48.obj" />
			</geometry>
		</collision>
		<collision>
			<origin xyz="0 0 0" />
			<geometry>
				<mesh filename="textured_objs_isaac/original_23.obj" />
			</geometry>
		</collision>
		<collision>
			<origin xyz="0 0 0" />
			<geometry>
				<mesh filename="textured_objs_isaac/original_67.obj" />
			</geometry>
		</collision>
		<collision>
			<origin xyz="0 0 0" />
			<geometry>
				<mesh filename="textured_objs_isaac/original_38.obj" />
			</geometry>
		</collision>
		<collision>
			<origin xyz="0 0 0" />
			<geometry>
				<mesh filename="textured_objs_isaac/original_68.obj" />
			</geometry>
		</collision>
		<collision>
			<origin xyz="0 0 0" />
			<geometry>
				<mesh filename="textured_objs_isaac/original_34.obj" />
			</geometry>
		</collision>
		<collision>
			<origin xyz="0 0 0" />
			<geometry>
				<mesh filename="textured_objs_isaac/original_42.obj" />
			</geometry>
		</collision>
		<collision>
			<origin xyz="0 0 0" />
			<geometry>
				<mesh filename="textured_objs_isaac/original_20.obj" />
			</geometry>
		</collision>
		<collision>
			<origin xyz="0 0 0" />
			<geometry>
				<mesh filename="textured_objs_isaac/original_32.obj" />
			</geometry>
		</collision>
		<collision>
			<origin xyz="0 0 0" />
			<geometry>
				<mesh filename="textured_objs_isaac/original_47.obj" />
			</geometry>
		</collision>
		<collision>
			<origin xyz="0 0 0" />
			<geometry>
				<mesh filename="textured_objs_isaac/original_40.obj" />
			</geometry>
		</collision>
		<collision>
			<origin xyz="0 0 0" />
			<geometry>
				<mesh filename="textured_objs_isaac/original_46.obj" />
			</geometry>
		</collision>
	</link>
	<joint name="joint_15" type="fixed">
		<origin rpy="1.570796326794897 0 -1.570796326794897" xyz="0 0 0" />
		<child link="link_15" />
		<parent link="base" />
	</joint>
</robot>