<?xml version='1.0' encoding='utf-8'?>
<robot name="partnet_19dff8164764e2a259f37b6e82c5e93">
	<link name="base" />
	<link name="link_0">
		<visual name="rotation_blade_1">
			<origin xyz="-0.018325304002647536 -0.05592899999999945 -0.23479860949070552" />
			<geometry>
				<mesh filename="textured_objs/original_2.obj" />
			</geometry>
		</visual>
		<visual name="rotation_blade_1">
			<origin xyz="-0.018325304002647536 -0.05592899999999945 -0.23479860949070552" />
			<geometry>
				<mesh filename="textured_objs/original_3.obj" />
			</geometry>
		</visual>
		<visual name="rotation_blade_1">
			<origin xyz="-0.018325304002647536 -0.05592899999999945 -0.23479860949070552" />
			<geometry>
				<mesh filename="textured_objs/original_5.obj" />
			</geometry>
		</visual>
		<visual name="rotation_blade_1">
			<origin xyz="-0.018325304002647536 -0.05592899999999945 -0.23479860949070552" />
			<geometry>
				<mesh filename="textured_objs/original_7.obj" />
			</geometry>
		</visual>
		<visual name="rotation_blade_1">
			<origin xyz="-0.018325304002647536 -0.05592899999999945 -0.23479860949070552" />
			<geometry>
				<mesh filename="textured_objs/original_4.obj" />
			</geometry>
		</visual>
		<collision>
			<origin xyz="-0.018325304002647536 -0.05592899999999945 -0.23479860949070552" />
			<geometry>
				<mesh filename="textured_objs/original_2.obj" />
			</geometry>
		</collision>
		<collision>
			<origin xyz="-0.018325304002647536 -0.05592899999999945 -0.23479860949070552" />
			<geometry>
				<mesh filename="textured_objs/original_3.obj" />
			</geometry>
		</collision>
		<collision>
			<origin xyz="-0.018325304002647536 -0.05592899999999945 -0.23479860949070552" />
			<geometry>
				<mesh filename="textured_objs/original_5.obj" />
			</geometry>
		</collision>
		<collision>
			<origin xyz="-0.018325304002647536 -0.05592899999999945 -0.23479860949070552" />
			<geometry>
				<mesh filename="textured_objs/original_7.obj" />
			</geometry>
		</collision>
		<collision>
			<origin xyz="-0.018325304002647536 -0.05592899999999945 -0.23479860949070552" />
			<geometry>
				<mesh filename="textured_objs/original_4.obj" />
			</geometry>
		</collision>
	</link>
	<joint name="joint_0" type="revolute">
		<origin xyz="0.018325304002647536 0.05592899999999945 0.23479860949070552" />
		<axis xyz="0 -1 0" />
		<child link="link_0" />
		<parent link="link_1" />
		<limit lower="-2.9216811678385075" upper="-0.0" />
	</joint>
	<link name="link_1">
		<visual name="base_body_2">
			<origin xyz="0 0 0" />
			<geometry>
				<mesh filename="textured_objs/original_6.obj" />
			</geometry>
		</visual>
		<collision>
			<origin xyz="0 0 0" />
			<geometry>
				<mesh filename="textured_objs/original_6.obj" />
			</geometry>
		</collision>
	</link>
	<joint name="joint_1" type="fixed">
		<origin rpy="1.570796326794897 0 -1.570796326794897" xyz="0 0 0" />
		<child link="link_1" />
		<parent link="base" />
	</joint>
</robot>