<?xml version="1.0" ?>
<robot name="partnet_7028b24b7d64efaf3194539af1047dcf">
	<link name="base"/>
	<link name="link_0">
		<visual name="door_frame-10">
			<origin xyz="-0.511112457240624 -0.7355 -0.49444429491836783"/>
			<geometry>
				<mesh filename="textured_objs_isaac/original_5_obj"/>
			</geometry>
		</visual>
		<visual name="door_frame-10">
			<origin xyz="-0.511112457240624 -0.7355 -0.49444429491836783"/>
			<geometry>
				<mesh filename="textured_objs_isaac/original_13_obj"/>
			</geometry>
		</visual>
		<visual name="door_frame-10">
			<origin xyz="-0.511112457240624 -0.7355 -0.49444429491836783"/>
			<geometry>
				<mesh filename="textured_objs_isaac/original_4_obj"/>
			</geometry>
		</visual>
		<visual name="door_frame-10">
			<origin xyz="-0.511112457240624 -0.7355 -0.49444429491836783"/>
			<geometry>
				<mesh filename="textured_objs_isaac/original_3_obj"/>
			</geometry>
		</visual>
		<visual name="door_frame-10">
			<origin xyz="-0.511112457240624 -0.7355 -0.49444429491836783"/>
			<geometry>
				<mesh filename="textured_objs_isaac/original_11_obj"/>
			</geometry>
		</visual>
		<visual name="door_frame-10">
			<origin xyz="-0.511112457240624 -0.7355 -0.49444429491836783"/>
			<geometry>
				<mesh filename="textured_objs_isaac/original_12_obj"/>
			</geometry>
		</visual>
		<visual name="handle-11">
			<origin xyz="-0.511112457240624 -0.7355 -0.49444429491836783"/>
			<geometry>
				<mesh filename="textured_objs_isaac/original_15_obj"/>
			</geometry>
		</visual>
		<visual name="handle-11">
			<origin xyz="-0.511112457240624 -0.7355 -0.49444429491836783"/>
			<geometry>
				<mesh filename="textured_objs_isaac/original_16_obj"/>
			</geometry>
		</visual>
		<visual name="handle-11">
			<origin xyz="-0.511112457240624 -0.7355 -0.49444429491836783"/>
			<geometry>
				<mesh filename="textured_objs_isaac/original_14_obj"/>
			</geometry>
		</visual>
		<collision>
			<origin xyz="-0.511112457240624 -0.7355 -0.49444429491836783"/>
			<geometry>
				<mesh filename="textured_objs_isaac/original_5_obj"/>
			</geometry>
		</collision>
		<collision>
			<origin xyz="-0.511112457240624 -0.7355 -0.49444429491836783"/>
			<geometry>
				<mesh filename="textured_objs_isaac/original_13_obj"/>
			</geometry>
		</collision>
		<collision>
			<origin xyz="-0.511112457240624 -0.7355 -0.49444429491836783"/>
			<geometry>
				<mesh filename="textured_objs_isaac/original_4_obj"/>
			</geometry>
		</collision>
		<collision>
			<origin xyz="-0.511112457240624 -0.7355 -0.49444429491836783"/>
			<geometry>
				<mesh filename="textured_objs_isaac/original_3_obj"/>
			</geometry>
		</collision>
		<collision>
			<origin xyz="-0.511112457240624 -0.7355 -0.49444429491836783"/>
			<geometry>
				<mesh filename="textured_objs_isaac/original_11_obj"/>
			</geometry>
		</collision>
		<collision>
			<origin xyz="-0.511112457240624 -0.7355 -0.49444429491836783"/>
			<geometry>
				<mesh filename="textured_objs_isaac/original_12_obj"/>
			</geometry>
		</collision>
		<collision>
			<origin xyz="-0.511112457240624 -0.7355 -0.49444429491836783"/>
			<geometry>
				<mesh filename="textured_objs_isaac/original_15_obj"/>
			</geometry>
		</collision>
		<collision>
			<origin xyz="-0.511112457240624 -0.7355 -0.49444429491836783"/>
			<geometry>
				<mesh filename="textured_objs_isaac/original_16_obj"/>
			</geometry>
		</collision>
		<collision>
			<origin xyz="-0.511112457240624 -0.7355 -0.49444429491836783"/>
			<geometry>
				<mesh filename="textured_objs_isaac/original_14_obj"/>
			</geometry>
		</collision>
	</link>
	<joint name="joint_0" type="revolute">
		<origin xyz="0.511112457240624 0.7355 0.49444429491836783"/>
		<axis xyz="0 1 0"/>
		<child link="link_0"/>
		<parent link="link_1"/>
		<limit lower="-0.0" upper="3.141592653589793"/>
	</joint>
	<link name="link_1">
		<visual name="frame-8">
			<origin xyz="0 0 0"/>
			<geometry>
				<mesh filename="textured_objs_isaac/new_1_obj"/>
			</geometry>
		</visual>
		<visual name="frame-8">
			<origin xyz="0 0 0"/>
			<geometry>
				<mesh filename="textured_objs_isaac/new_0_obj"/>
			</geometry>
		</visual>
		<visual name="foot-12">
			<origin xyz="0 0 0"/>
			<geometry>
				<mesh filename="textured_objs_isaac/original_19_obj"/>
			</geometry>
		</visual>
		<visual name="foot-13">
			<origin xyz="0 0 0"/>
			<geometry>
				<mesh filename="textured_objs_isaac/original_20_obj"/>
			</geometry>
		</visual>
		<visual name="foot-14">
			<origin xyz="0 0 0"/>
			<geometry>
				<mesh filename="textured_objs_isaac/original_18_obj"/>
			</geometry>
		</visual>
		<visual name="foot-15">
			<origin xyz="0 0 0"/>
			<geometry>
				<mesh filename="textured_objs_isaac/original_17_obj"/>
			</geometry>
		</visual>
		<collision>
			<origin xyz="0 0 0"/>
			<geometry>
				<mesh filename="textured_objs_isaac/new_1_obj"/>
			</geometry>
		</collision>
		<collision>
			<origin xyz="0 0 0"/>
			<geometry>
				<mesh filename="textured_objs_isaac/new_0_obj"/>
			</geometry>
		</collision>
		<collision>
			<origin xyz="0 0 0"/>
			<geometry>
				<mesh filename="textured_objs_isaac/original_19_obj"/>
			</geometry>
		</collision>
		<collision>
			<origin xyz="0 0 0"/>
			<geometry>
				<mesh filename="textured_objs_isaac/original_20_obj"/>
			</geometry>
		</collision>
		<collision>
			<origin xyz="0 0 0"/>
			<geometry>
				<mesh filename="textured_objs_isaac/original_18_obj"/>
			</geometry>
		</collision>
		<collision>
			<origin xyz="0 0 0"/>
			<geometry>
				<mesh filename="textured_objs_isaac/original_17_obj"/>
			</geometry>
		</collision>
	</link>
	<joint name="joint_1" type="fixed">
		<origin rpy="1.570796326794897 0 -1.570796326794897" xyz="0 0 0"/>
		<child link="link_1"/>
		<parent link="base"/>
	</joint>
</robot>
