<?xml version="1.0" ?>
<robot name="partnet_7028b24b7d64efaf3194539af1047dcf">
	<link name="base"/>
	<link name="link_0">
		<visual name="door_frame_10">
			<origin xyz="-0.511112457240624 -0.7355 -0.49444429491836783"/>
			<geometry>
				<mesh filename="textured_objs/original_5.obj"/>
			</geometry>
		</visual>
		<visual name="door_frame_10">
			<origin xyz="-0.511112457240624 -0.7355 -0.49444429491836783"/>
			<geometry>
				<mesh filename="textured_objs/original_13.obj"/>
			</geometry>
		</visual>
		<visual name="door_frame_10">
			<origin xyz="-0.511112457240624 -0.7355 -0.49444429491836783"/>
			<geometry>
				<mesh filename="textured_objs/original_4.obj"/>
			</geometry>
		</visual>
		<visual name="door_frame_10">
			<origin xyz="-0.511112457240624 -0.7355 -0.49444429491836783"/>
			<geometry>
				<mesh filename="textured_objs/original_3.obj"/>
			</geometry>
		</visual>
		<visual name="door_frame_10">
			<origin xyz="-0.511112457240624 -0.7355 -0.49444429491836783"/>
			<geometry>
				<mesh filename="textured_objs/original_11.obj"/>
			</geometry>
		</visual>
		<visual name="door_frame_10">
			<origin xyz="-0.511112457240624 -0.7355 -0.49444429491836783"/>
			<geometry>
				<mesh filename="textured_objs/original_12.obj"/>
			</geometry>
		</visual>
		<visual name="handle_11">
			<origin xyz="-0.511112457240624 -0.7355 -0.49444429491836783"/>
			<geometry>
				<mesh filename="textured_objs/original_15.obj"/>
			</geometry>
		</visual>
		<visual name="handle_11">
			<origin xyz="-0.511112457240624 -0.7355 -0.49444429491836783"/>
			<geometry>
				<mesh filename="textured_objs/original_16.obj"/>
			</geometry>
		</visual>
		<visual name="handle_11">
			<origin xyz="-0.511112457240624 -0.7355 -0.49444429491836783"/>
			<geometry>
				<mesh filename="textured_objs/original_14.obj"/>
			</geometry>
		</visual>
		<collision>
			<origin xyz="-0.511112457240624 -0.7355 -0.49444429491836783"/>
			<geometry>
				<mesh filename="textured_objs/original_5.obj"/>
			</geometry>
		</collision>
		<collision>
			<origin xyz="-0.511112457240624 -0.7355 -0.49444429491836783"/>
			<geometry>
				<mesh filename="textured_objs/original_13.obj"/>
			</geometry>
		</collision>
		<collision>
			<origin xyz="-0.511112457240624 -0.7355 -0.49444429491836783"/>
			<geometry>
				<mesh filename="textured_objs/original_4.obj"/>
			</geometry>
		</collision>
		<collision>
			<origin xyz="-0.511112457240624 -0.7355 -0.49444429491836783"/>
			<geometry>
				<mesh filename="textured_objs/original_3.obj"/>
			</geometry>
		</collision>
		<collision>
			<origin xyz="-0.511112457240624 -0.7355 -0.49444429491836783"/>
			<geometry>
				<mesh filename="textured_objs/original_11.obj"/>
			</geometry>
		</collision>
		<collision>
			<origin xyz="-0.511112457240624 -0.7355 -0.49444429491836783"/>
			<geometry>
				<mesh filename="textured_objs/original_12.obj"/>
			</geometry>
		</collision>
		<collision>
			<origin xyz="-0.511112457240624 -0.7355 -0.49444429491836783"/>
			<geometry>
				<mesh filename="textured_objs/original_15.obj"/>
			</geometry>
		</collision>
		<collision>
			<origin xyz="-0.511112457240624 -0.7355 -0.49444429491836783"/>
			<geometry>
				<mesh filename="textured_objs/original_16.obj"/>
			</geometry>
		</collision>
		<collision>
			<origin xyz="-0.511112457240624 -0.7355 -0.49444429491836783"/>
			<geometry>
				<mesh filename="textured_objs/original_14.obj"/>
			</geometry>
		</collision>
	</link>
	<joint name="joint_0" type="revolute">
		<origin xyz="0.511112457240624 0.7355 0.49444429491836783"/>
		<axis xyz="0 1 0"/>
		<child link="link_0"/>
		<parent link="link_1"/>
		<limit lower="-0.0" upper="3.141592653589793"/>
	</joint>
	<link name="link_1">
		<visual name="frame_8">
			<origin xyz="0 0 0"/>
			<geometry>
				<mesh filename="textured_objs/new_1.obj"/>
			</geometry>
		</visual>
		<visual name="frame_8">
			<origin xyz="0 0 0"/>
			<geometry>
				<mesh filename="textured_objs/new_0.obj"/>
			</geometry>
		</visual>
		<visual name="foot_12">
			<origin xyz="0 0 0"/>
			<geometry>
				<mesh filename="textured_objs/original_19.obj"/>
			</geometry>
		</visual>
		<visual name="foot_13">
			<origin xyz="0 0 0"/>
			<geometry>
				<mesh filename="textured_objs/original_20.obj"/>
			</geometry>
		</visual>
		<visual name="foot_14">
			<origin xyz="0 0 0"/>
			<geometry>
				<mesh filename="textured_objs/original_18.obj"/>
			</geometry>
		</visual>
		<visual name="foot_15">
			<origin xyz="0 0 0"/>
			<geometry>
				<mesh filename="textured_objs/original_17.obj"/>
			</geometry>
		</visual>
		<collision>
			<origin xyz="0 0 0"/>
			<geometry>
				<mesh filename="textured_objs/new_1.obj"/>
			</geometry>
		</collision>
		<collision>
			<origin xyz="0 0 0"/>
			<geometry>
				<mesh filename="textured_objs/new_0.obj"/>
			</geometry>
		</collision>
		<collision>
			<origin xyz="0 0 0"/>
			<geometry>
				<mesh filename="textured_objs/original_19.obj"/>
			</geometry>
		</collision>
		<collision>
			<origin xyz="0 0 0"/>
			<geometry>
				<mesh filename="textured_objs/original_20.obj"/>
			</geometry>
		</collision>
		<collision>
			<origin xyz="0 0 0"/>
			<geometry>
				<mesh filename="textured_objs/original_18.obj"/>
			</geometry>
		</collision>
		<collision>
			<origin xyz="0 0 0"/>
			<geometry>
				<mesh filename="textured_objs/original_17.obj"/>
			</geometry>
		</collision>
	</link>
	<joint name="joint_1" type="fixed">
		<origin rpy="1.570796326794897 0 -1.570796326794897" xyz="0 0 0"/>
		<child link="link_1"/>
		<parent link="base"/>
	</joint>
</robot>
